Workbook

Sheet How to use
A1: Downtime Log & Pareto
A2: Version 1.0
B4: What this does
B6: Record every stop with a reason. The Pareto sheet ranks reasons by minutes lost so you can see the few causes behind most of your downtime, for any date range and any machine.
B7: Colour key
B9: Yellow cells are for you to fill in.
B10: Grey cells are calculated. Don't type over them.
B11: Steps
B13: 1. Setup: list your machines, and edit the reason list to match how your plant talks about stops. Each reason has a category (Breakdown, Material, and so on) that you can also rename.
B14: 2. Downtime Log: one row per stop. Enter start and end times, or type the minutes directly if you only know the duration. Stops that cross midnight are handled automatically.
B15: 3. Pareto: choose a date range and, optionally, one machine. Reasons are ranked automatically, with the cumulative percentage and a chart.
B16: 4. By Machine: total downtime and stop counts per machine for the same date range.
B17: 5. The rows marked EXAMPLE show the expected format. Before you start, select their yellow cells and press Delete. Don't delete whole rows.
B18: Tips
... B22: The Check column on the log should say OK. A stop counts when its duration is more than 0 minutes. Rows without a date, or with minutes that aren't a number of 0 or more, are left out of the totals.

Sheet Setup
A1: Setup
A2: Machines and downtime reasons used by the drop-downs.
A4: Machine | B4: Check | D4: Downtime reason | E4: Category | F4: Check
A5: Press 01 | B5: =IF(A5="","",IF(SUMPRODUCT(--($A$5:A5=A5))>1,"Duplicate: only the first row is used","")) | D5: Mechanical breakdown | E5: Breakdown | F5: =IF(D5="","",IF(SUMPRODUCT(--($D$5:D5=D5))>1,"Duplicate: only the first row is used",""))
A6: CNC Lathe 02 | B6: =IF(A6="","",IF(SUMPRODUCT(--($A$5:A6=A6))>1,"Duplicate: only the first row is used","")) | D6: Electrical / controls fault | E6: Breakdown | F6: =IF(D6="","",IF(SUMPRODUCT(--($D$5:D6=D6))>1,"Duplicate: only the first row is used",""))
A7: Packaging Line A | B7: =IF(A7="","",IF(SUMPRODUCT(--($A$5:A7=A7))>1,"Duplicate: only the first row is used","")) | D7: Tooling failure | E7: Breakdown | F7: =IF(D7="","",IF(SUMPRODUCT(--($D$5:D7=D7))>1,"Duplicate: only the first row is used",""))
B8: =IF(A8="","",IF(SUMPRODUCT(--($A$5:A8=A8))>1,"Duplicate: only the first row is used","")) | D8: Changeover / setup | E8: Setup & adjustment | F8: =IF(D8="","",IF(SUMPRODUCT(--($D$5:D8=D8))>1,"Duplicate: only the first row is used",""))
B9: =IF(A9="","",IF(SUMPRODUCT(--($A$5:A9=A9))>1,"Duplicate: only the first row is used","")) | D9: Adjustment / tuning | E9: Setup & adjustment | F9: =IF(D9="","",IF(SUMPRODUCT(--($D$5:D9=D9))>1,"Duplicate: only the first row is used",""))
B10: =IF(A10="","",IF(SUMPRODUCT(--($A$5:A10=A10))>1,"Duplicate: only the first row is used","")) | D10: Waiting for material | E10: Material | F10: =IF(D10="","",IF(SUMPRODUCT(--($D$5:D10=D10))>1,"Duplicate: only the first row is used",""))
B11: =IF(A11="","",IF(SUMPRODUCT(--($A$5:A11=A11))>1,"Duplicate: only the first row is used","")) | D11: Waiting for upstream process | E11: Material | F11: =IF(D11="","",IF(SUMPRODUCT(--($D$5:D11=D11))>1,"Duplicate: only the first row is used",""))
B12: =IF(A12="","",IF(SUMPRODUCT(--($A$5:A12=A12))>1,"Duplicate: only the first row is used","")) | D12: Quality hold / inspection | E12: Quality | F12: =IF(D12="","",IF(SUMPRODUCT(--($D$5:D12=D12))>1,"Duplicate: only the first row is used",""))
B13: =IF(A13="","",IF(SUMPRODUCT(--($A$5:A13=A13))>1,"Duplicate: only the first row is used","")) | D13: No operator available | E13: Labor | F13: =IF(D13="","",IF(SUMPRODUCT(--($D$5:D13=D13))>1,"Duplicate: only the first row is used",""))
B14: =IF(A14="","",IF(SUMPRODUCT(--($A$5:A14=A14))>1,"Duplicate: only the first row is used","")) | D14: Planned maintenance | E14: Planned | F14: =IF(D14="","",IF(SUMPRODUCT(--($D$5:D14=D14))>1,"Duplicate: only the first row is used",""))
B15: =IF(A15="","",IF(SUMPRODUCT(--($A$5:A15=A15))>1,"Duplicate: only the first row is used","")) | D15: Meeting / training | E15: Planned | F15: =IF(D15="","",IF(SUMPRODUCT(--($D$5:D15=D15))>1,"Duplicate: only the first row is used",""))
B16: =IF(A16="","",IF(SUMPRODUCT(--($A$5:A16=A16))>1,"Duplicate: only the first row is used","")) | D16: Other (describe in notes) | E16: Other | F16: =IF(D16="","",IF(SUMPRODUCT(--($D$5:D16=D16))>1,"Duplicate: only the first row is used",""))
B17: =IF(A17="","",IF(SUMPRODUCT(--($A$5:A17=A17))>1,"Duplicate: only the first row is used","")) | F17: =IF(D17="","",IF(SUMPRODUCT(--($D$5:D17=D17))>1,"Duplicate: only the first row is used",""))
B18: =IF(A18="","",IF(SUMPRODUCT(--($A$5:A18=A18))>1,"Duplicate: only the first row is used","")) | F18: =IF(D18="","",IF(SUMPRODUCT(--($D$5:D18=D18))>1,"Duplicate: only the first row is used",""))
B19: =IF(A19="","",IF(SUMPRODUCT(--($A$5:A19=A19))>1,"Duplicate: only the first row is used","")) | F19: =IF(D19="","",IF(SUMPRODUCT(--($D$5:D19=D19))>1,"Duplicate: only the first row is used",""))
B20: =IF(A20="","",IF(SUMPRODUCT(--($A$5:A20=A20))>1,"Duplicate: only the first row is used","")) | F20: =IF(D20="","",IF(SUMPRODUCT(--($D$5:D20=D20))>1,"Duplicate: only the first row is used",""))
B21: =IF(A21="","",IF(SUMPRODUCT(--($A$5:A21=A21))>1,"Duplicate: only the first row is used","")) | F21: =IF(D21="","",IF(SUMPRODUCT(--($D$5:D21=D21))>1,"Duplicate: only the first row is used",""))
B22: =IF(A22="","",IF(SUMPRODUCT(--($A$5:A22=A22))>1,"Duplicate: only the first row is used","")) | F22: =IF(D22="","",IF(SUMPRODUCT(--($D$5:D22=D22))>1,"Duplicate: only the first row is used",""))
B23: =IF(A23="","",IF(SUMPRODUCT(--($A$5:A23=A23))>1,"Duplicate: only the first row is used","")) | F23: =IF(D23="","",IF(SUMPRODUCT(--($D$5:D23=D23))>1,"Duplicate: only the first row is used",""))
B24: =IF(A24="","",IF(SUMPRODUCT(--($A$5:A24=A24))>1,"Duplicate: only the first row is used","")) | F24: =IF(D24="","",IF(SUMPRODUCT(--($D$5:D24=D24))>1,"Duplicate: only the first row is used",""))
B25: =IF(A25="","",IF(SUMPRODUCT(--($A$5:A25=A25))>1,"Duplicate: only the first row is used","")) | F25: =IF(D25="","",IF(SUMPRODUCT(--($D$5:D25=D25))>1,"Duplicate: only the first row is used",""))
B26: =IF(A26="","",IF(SUMPRODUCT(--($A$5:A26=A26))>1,"Duplicate: only the first row is used","")) | F26: =IF(D26="","",IF(SUMPRODUCT(--($D$5:D26=D26))>1,"Duplicate: only the first row is used",""))
B27: =IF(A27="","",IF(SUMPRODUCT(--($A$5:A27=A27))>1,"Duplicate: only the first row is used","")) | F27: =IF(D27="","",IF(SUMPRODUCT(--($D$5:D27=D27))>1,"Duplicate: only the first row is used",""))
B28: =IF(A28="","",IF(SUMPRODUCT(--($A$5:A28=A28))>1,"Duplicate: only the first row is used","")) | F28: =IF(D28="","",IF(SUMPRODUCT(--($D$5:D28=D28))>1,"Duplicate: only the first row is used",""))
... B34: =IF(A34="","",IF(SUMPRODUCT(--($A$5:A34=A34))>1,"Duplicate: only the first row is used","")) | F34: =IF(D34="","",IF(SUMPRODUCT(--($D$5:D34=D34))>1,"Duplicate: only the first row is used",""))

Sheet Downtime Log
A1: Downtime Log
A2: One row per stop. Use start/end times, or type minutes if you only know the duration.
A4: Date | B4: Shift | C4: Machine | D4: Start (hh:mm) | E4: End (hh:mm) | F4: Minutes (if no start/end) | G4: Duration (min) | H4: Reason | I4: Category | J4: Notes | K4: Check
A5: 46266 | B5: Day | C5: Press 01 | D5: 0.30208333 | E5: 0.32638889 | G5: =IF(F5<>"",IF(AND(ISNUMBER(F5),N(F5)>=0),F5,""),IF(AND(ISNUMBER(D5),ISNUMBER(E5)),ROUND(MOD(E5-D5,1)*1440,0),"")) -> 35 | H5: Changeover / setup | I5: =IF(H5="","",IF(SUMPRODUCT(MAX((Setup!$D$5:$D$34=H5)*(35-ROW(Setup!$D$5:$D$34))))=0,"Not in Setup",INDEX(Setup!$E$5:$E$34,31-SUMPRODUCT(MAX((Setup!$D$5:$D$34=H5)*(35-ROW(Setup!$D$5:$D$34))))))) -> Setup & adjustment | J5: EXAMPLE - Die change | K5: =IF(AND(A5="",C5="",D5="",E5="",F5="",H5=""),"",IF(NOT(ISNUMBER(A5)),"Enter a date",IF(AND(F5<>"",OR(NOT(ISNUMBER(F5)),N(F5)<0)),"Minutes must be a number of 0 or more",IF(G5="","Enter start and end times, or minutes",IF(C5="","Pick a machine",IF(SUMPRODUCT(--(Setup!$A$5:$A$34=C5))=0,"Machine not in Setup",IF(H5="","Pick a reason (counted as unclassified)",IF(I5="Not in Setup","Reason not in Setup (counted as unclassified)",IF(N(G5)=0,"0 minutes: not counted as a stop","OK"))))))))) -> OK
A6: 46266 | B6: Day | C6: Press 01 | D6: 0.42013889 | E6: 0.43055556 | G6: =IF(F6<>"",IF(AND(ISNUMBER(F6),N(F6)>=0),F6,""),IF(AND(ISNUMBER(D6),ISNUMBER(E6)),ROUND(MOD(E6-D6,1)*1440,0),"")) -> 15 | H6: Waiting for material | I6: =IF(H6="","",IF(SUMPRODUCT(MAX((Setup!$D$5:$D$34=H6)*(35-ROW(Setup!$D$5:$D$34))))=0,"Not in Setup",INDEX(Setup!$E$5:$E$34,31-SUMPRODUCT(MAX((Setup!$D$5:$D$34=H6)*(35-ROW(Setup!$D$5:$D$34))))))) -> Material | J6: EXAMPLE | K6: =IF(AND(A6="",C6="",D6="",E6="",F6="",H6=""),"",IF(NOT(ISNUMBER(A6)),"Enter a date",IF(AND(F6<>"",OR(NOT(ISNUMBER(F6)),N(F6)<0)),"Minutes must be a number of 0 or more",IF(G6="","Enter start and end times, or minutes",IF(C6="","Pick a machine",IF(SUMPRODUCT(--(Setup!$A$5:$A$34=C6))=0,"Machine not in Setup",IF(H6="","Pick a reason (counted as unclassified)",IF(I6="Not in Setup","Reason not in Setup (counted as unclassified)",IF(N(G6)=0,"0 minutes: not counted as a stop","OK"))))))))) -> OK
A7: 46266 | B7: Day | C7: CNC Lathe 02 | D7: 0.375 | E7: 0.41666667 | G7: =IF(F7<>"",IF(AND(ISNUMBER(F7),N(F7)>=0),F7,""),IF(AND(ISNUMBER(D7),ISNUMBER(E7)),ROUND(MOD(E7-D7,1)*1440,0),"")) -> 60 | H7: Tooling failure | I7: =IF(H7="","",IF(SUMPRODUCT(MAX((Setup!$D$5:$D$34=H7)*(35-ROW(Setup!$D$5:$D$34))))=0,"Not in Setup",INDEX(Setup!$E$5:$E$34,31-SUMPRODUCT(MAX((Setup!$D$5:$D$34=H7)*(35-ROW(Setup!$D$5:$D$34))))))) -> Breakdown | J7: EXAMPLE - Insert broke | K7: =IF(AND(A7="",C7="",D7="",E7="",F7="",H7=""),"",IF(NOT(ISNUMBER(A7)),"Enter a date",IF(AND(F7<>"",OR(NOT(ISNUMBER(F7)),N(F7)<0)),"Minutes must be a number of 0 or more",IF(G7="","Enter start and end times, or minutes",IF(C7="","Pick a machine",IF(SUMPRODUCT(--(Setup!$A$5:$A$34=C7))=0,"Machine not in Setup",IF(H7="","Pick a reason (counted as unclassified)",IF(I7="Not in Setup","Reason not in Setup (counted as unclassified)",IF(N(G7)=0,"0 minutes: not counted as a stop","OK"))))))))) -> OK
A8: 46266 | B8: Night | C8: Packaging Line A | D8: 0.98611111 | E8: 0.017361111 | G8: =IF(F8<>"",IF(AND(ISNUMBER(F8),N(F8)>=0),F8,""),IF(AND(ISNUMBER(D8),ISNUMBER(E8)),ROUND(MOD(E8-D8,1)*1440,0),"")) -> 45 | H8: Mechanical breakdown | I8: =IF(H8="","",IF(SUMPRODUCT(MAX((Setup!$D$5:$D$34=H8)*(35-ROW(Setup!$D$5:$D$34))))=0,"Not in Setup",INDEX(Setup!$E$5:$E$34,31-SUMPRODUCT(MAX((Setup!$D$5:$D$34=H8)*(35-ROW(Setup!$D$5:$D$34))))))) -> Breakdown | J8: EXAMPLE - Conveyor jam, crossed midnight | K8: =IF(AND(A8="",C8="",D8="",E8="",F8="",H8=""),"",IF(NOT(ISNUMBER(A8)),"Enter a date",IF(AND(F8<>"",OR(NOT(ISNUMBER(F8)),N(F8)<0)),"Minutes must be a number of 0 or more",IF(G8="","Enter start and end times, or minutes",IF(C8="","Pick a machine",IF(SUMPRODUCT(--(Setup!$A$5:$A$34=C8))=0,"Machine not in Setup",IF(H8="","Pick a reason (counted as unclassified)",IF(I8="Not in Setup","Reason not in Setup (counted as unclassified)",IF(N(G8)=0,"0 minutes: not counted as a stop","OK"))))))))) -> OK
A9: 46267 | B9: Day | C9: Press 01 | F9: 55 | G9: =IF(F9<>"",IF(AND(ISNUMBER(F9),N(F9)>=0),F9,""),IF(AND(ISNUMBER(D9),ISNUMBER(E9)),ROUND(MOD(E9-D9,1)*1440,0),"")) -> 55 | H9: Mechanical breakdown | I9: =IF(H9="","",IF(SUMPRODUCT(MAX((Setup!$D$5:$D$34=H9)*(35-ROW(Setup!$D$5:$D$34))))=0,"Not in Setup",INDEX(Setup!$E$5:$E$34,31-SUMPRODUCT(MAX((Setup!$D$5:$D$34=H9)*(35-ROW(Setup!$D$5:$D$34))))))) -> Breakdown | J9: EXAMPLE - Minutes typed directly | K9: =IF(AND(A9="",C9="",D9="",E9="",F9="",H9=""),"",IF(NOT(ISNUMBER(A9)),"Enter a date",IF(AND(F9<>"",OR(NOT(ISNUMBER(F9)),N(F9)<0)),"Minutes must be a number of 0 or more",IF(G9="","Enter start and end times, or minutes",IF(C9="","Pick a machine",IF(SUMPRODUCT(--(Setup!$A$5:$A$34=C9))=0,"Machine not in Setup",IF(H9="","Pick a reason (counted as unclassified)",IF(I9="Not in Setup","Reason not in Setup (counted as unclassified)",IF(N(G9)=0,"0 minutes: not counted as a stop","OK"))))))))) -> OK
A10: 46267 | B10: Day | C10: Packaging Line A | D10: 0.54166667 | E10: 0.5625 | G10: =IF(F10<>"",IF(AND(ISNUMBER(F10),N(F10)>=0),F10,""),IF(AND(ISNUMBER(D10),ISNUMBER(E10)),ROUND(MOD(E10-D10,1)*1440,0),"")) -> 30 | H10: Changeover / setup | I10: =IF(H10="","",IF(SUMPRODUCT(MAX((Setup!$D$5:$D$34=H10)*(35-ROW(Setup!$D$5:$D$34))))=0,"Not in Setup",INDEX(Setup!$E$5:$E$34,31-SUMPRODUCT(MAX((Setup!$D$5:$D$34=H10)*(35-ROW(Setup!$D$5:$D$34))))))) -> Setup & adjustment | J10: EXAMPLE | K10: =IF(AND(A10="",C10="",D10="",E10="",F10="",H10=""),"",IF(NOT(ISNUMBER(A10)),"Enter a date",IF(AND(F10<>"",OR(NOT(ISNUMBER(F10)),N(F10)<0)),"Minutes must be a number of 0 or more",IF(G10="","Enter start and end times, or minutes",IF(C10="","Pick a machine",IF(SUMPRODUCT(--(Setup!$A$5:$A$34=C10))=0,"Machine not in Setup",IF(H10="","Pick a reason (counted as unclassified)",IF(I10="Not in Setup","Reason not in Setup (counted as unclassified)",IF(N(G10)=0,"0 minutes: not counted as a stop","OK"))))))))) -> OK
A11: 46267 | B11: Day | C11: CNC Lathe 02 | D11: 0.59027778 | E11: 0.60069444 | G11: =IF(F11<>"",IF(AND(ISNUMBER(F11),N(F11)>=0),F11,""),IF(AND(ISNUMBER(D11),ISNUMBER(E11)),ROUND(MOD(E11-D11,1)*1440,0),"")) -> 15 | H11: Quality hold / inspection | I11: =IF(H11="","",IF(SUMPRODUCT(MAX((Setup!$D$5:$D$34=H11)*(35-ROW(Setup!$D$5:$D$34))))=0,"Not in Setup",INDEX(Setup!$E$5:$E$34,31-SUMPRODUCT(MAX((Setup!$D$5:$D$34=H11)*(35-ROW(Setup!$D$5:$D$34))))))) -> Quality | J11: EXAMPLE | K11: =IF(AND(A11="",C11="",D11="",E11="",F11="",H11=""),"",IF(NOT(ISNUMBER(A11)),"Enter a date",IF(AND(F11<>"",OR(NOT(ISNUMBER(F11)),N(F11)<0)),"Minutes must be a number of 0 or more",IF(G11="","Enter start and end times, or minutes",IF(C11="","Pick a machine",IF(SUMPRODUCT(--(Setup!$A$5:$A$34=C11))=0,"Machine not in Setup",IF(H11="","Pick a reason (counted as unclassified)",IF(I11="Not in Setup","Reason not in Setup (counted as unclassified)",IF(N(G11)=0,"0 minutes: not counted as a stop","OK"))))))))) -> OK
G12: =IF(F12<>"",IF(AND(ISNUMBER(F12),N(F12)>=0),F12,""),IF(AND(ISNUMBER(D12),ISNUMBER(E12)),ROUND(MOD(E12-D12,1)*1440,0),"")) | I12: =IF(H12="","",IF(SUMPRODUCT(MAX((Setup!$D$5:$D$34=H12)*(35-ROW(Setup!$D$5:$D$34))))=0,"Not in Setup",INDEX(Setup!$E$5:$E$34,31-SUMPRODUCT(MAX((Setup!$D$5:$D$34=H12)*(35-ROW(Setup!$D$5:$D$34))))))) | K12: =IF(AND(A12="",C12="",D12="",E12="",F12="",H12=""),"",IF(NOT(ISNUMBER(A12)),"Enter a date",IF(AND(F12<>"",OR(NOT(ISNUMBER(F12)),N(F12)<0)),"Minutes must be a number of 0 or more",IF(G12="","Enter start and end times, or minutes",IF(C12="","Pick a machine",IF(SUMPRODUCT(--(Setup!$A$5:$A$34=C12))=0,"Machine not in Setup",IF(H12="","Pick a reason (counted as unclassified)",IF(I12="Not in Setup","Reason not in Setup (counted as unclassified)",IF(N(G12)=0,"0 minutes: not counted as a stop","OK")))))))))
G13: =IF(F13<>"",IF(AND(ISNUMBER(F13),N(F13)>=0),F13,""),IF(AND(ISNUMBER(D13),ISNUMBER(E13)),ROUND(MOD(E13-D13,1)*1440,0),"")) | I13: =IF(H13="","",IF(SUMPRODUCT(MAX((Setup!$D$5:$D$34=H13)*(35-ROW(Setup!$D$5:$D$34))))=0,"Not in Setup",INDEX(Setup!$E$5:$E$34,31-SUMPRODUCT(MAX((Setup!$D$5:$D$34=H13)*(35-ROW(Setup!$D$5:$D$34))))))) | K13: =IF(AND(A13="",C13="",D13="",E13="",F13="",H13=""),"",IF(NOT(ISNUMBER(A13)),"Enter a date",IF(AND(F13<>"",OR(NOT(ISNUMBER(F13)),N(F13)<0)),"Minutes must be a number of 0 or more",IF(G13="","Enter start and end times, or minutes",IF(C13="","Pick a machine",IF(SUMPRODUCT(--(Setup!$A$5:$A$34=C13))=0,"Machine not in Setup",IF(H13="","Pick a reason (counted as unclassified)",IF(I13="Not in Setup","Reason not in Setup (counted as unclassified)",IF(N(G13)=0,"0 minutes: not counted as a stop","OK")))))))))
G14: =IF(F14<>"",IF(AND(ISNUMBER(F14),N(F14)>=0),F14,""),IF(AND(ISNUMBER(D14),ISNUMBER(E14)),ROUND(MOD(E14-D14,1)*1440,0),"")) | I14: =IF(H14="","",IF(SUMPRODUCT(MAX((Setup!$D$5:$D$34=H14)*(35-ROW(Setup!$D$5:$D$34))))=0,"Not in Setup",INDEX(Setup!$E$5:$E$34,31-SUMPRODUCT(MAX((Setup!$D$5:$D$34=H14)*(35-ROW(Setup!$D$5:$D$34))))))) | K14: =IF(AND(A14="",C14="",D14="",E14="",F14="",H14=""),"",IF(NOT(ISNUMBER(A14)),"Enter a date",IF(AND(F14<>"",OR(NOT(ISNUMBER(F14)),N(F14)<0)),"Minutes must be a number of 0 or more",IF(G14="","Enter start and end times, or minutes",IF(C14="","Pick a machine",IF(SUMPRODUCT(--(Setup!$A$5:$A$34=C14))=0,"Machine not in Setup",IF(H14="","Pick a reason (counted as unclassified)",IF(I14="Not in Setup","Reason not in Setup (counted as unclassified)",IF(N(G14)=0,"0 minutes: not counted as a stop","OK")))))))))
G15: =IF(F15<>"",IF(AND(ISNUMBER(F15),N(F15)>=0),F15,""),IF(AND(ISNUMBER(D15),ISNUMBER(E15)),ROUND(MOD(E15-D15,1)*1440,0),"")) | I15: =IF(H15="","",IF(SUMPRODUCT(MAX((Setup!$D$5:$D$34=H15)*(35-ROW(Setup!$D$5:$D$34))))=0,"Not in Setup",INDEX(Setup!$E$5:$E$34,31-SUMPRODUCT(MAX((Setup!$D$5:$D$34=H15)*(35-ROW(Setup!$D$5:$D$34))))))) | K15: =IF(AND(A15="",C15="",D15="",E15="",F15="",H15=""),"",IF(NOT(ISNUMBER(A15)),"Enter a date",IF(AND(F15<>"",OR(NOT(ISNUMBER(F15)),N(F15)<0)),"Minutes must be a number of 0 or more",IF(G15="","Enter start and end times, or minutes",IF(C15="","Pick a machine",IF(SUMPRODUCT(--(Setup!$A$5:$A$34=C15))=0,"Machine not in Setup",IF(H15="","Pick a reason (counted as unclassified)",IF(I15="Not in Setup","Reason not in Setup (counted as unclassified)",IF(N(G15)=0,"0 minutes: not counted as a stop","OK")))))))))
G16: =IF(F16<>"",IF(AND(ISNUMBER(F16),N(F16)>=0),F16,""),IF(AND(ISNUMBER(D16),ISNUMBER(E16)),ROUND(MOD(E16-D16,1)*1440,0),"")) | I16: =IF(H16="","",IF(SUMPRODUCT(MAX((Setup!$D$5:$D$34=H16)*(35-ROW(Setup!$D$5:$D$34))))=0,"Not in Setup",INDEX(Setup!$E$5:$E$34,31-SUMPRODUCT(MAX((Setup!$D$5:$D$34=H16)*(35-ROW(Setup!$D$5:$D$34))))))) | K16: =IF(AND(A16="",C16="",D16="",E16="",F16="",H16=""),"",IF(NOT(ISNUMBER(A16)),"Enter a date",IF(AND(F16<>"",OR(NOT(ISNUMBER(F16)),N(F16)<0)),"Minutes must be a number of 0 or more",IF(G16="","Enter start and end times, or minutes",IF(C16="","Pick a machine",IF(SUMPRODUCT(--(Setup!$A$5:$A$34=C16))=0,"Machine not in Setup",IF(H16="","Pick a reason (counted as unclassified)",IF(I16="Not in Setup","Reason not in Setup (counted as unclassified)",IF(N(G16)=0,"0 minutes: not counted as a stop","OK")))))))))
G17: =IF(F17<>"",IF(AND(ISNUMBER(F17),N(F17)>=0),F17,""),IF(AND(ISNUMBER(D17),ISNUMBER(E17)),ROUND(MOD(E17-D17,1)*1440,0),"")) | I17: =IF(H17="","",IF(SUMPRODUCT(MAX((Setup!$D$5:$D$34=H17)*(35-ROW(Setup!$D$5:$D$34))))=0,"Not in Setup",INDEX(Setup!$E$5:$E$34,31-SUMPRODUCT(MAX((Setup!$D$5:$D$34=H17)*(35-ROW(Setup!$D$5:$D$34))))))) | K17: =IF(AND(A17="",C17="",D17="",E17="",F17="",H17=""),"",IF(NOT(ISNUMBER(A17)),"Enter a date",IF(AND(F17<>"",OR(NOT(ISNUMBER(F17)),N(F17)<0)),"Minutes must be a number of 0 or more",IF(G17="","Enter start and end times, or minutes",IF(C17="","Pick a machine",IF(SUMPRODUCT(--(Setup!$A$5:$A$34=C17))=0,"Machine not in Setup",IF(H17="","Pick a reason (counted as unclassified)",IF(I17="Not in Setup","Reason not in Setup (counted as unclassified)",IF(N(G17)=0,"0 minutes: not counted as a stop","OK")))))))))
G18: =IF(F18<>"",IF(AND(ISNUMBER(F18),N(F18)>=0),F18,""),IF(AND(ISNUMBER(D18),ISNUMBER(E18)),ROUND(MOD(E18-D18,1)*1440,0),"")) | I18: =IF(H18="","",IF(SUMPRODUCT(MAX((Setup!$D$5:$D$34=H18)*(35-ROW(Setup!$D$5:$D$34))))=0,"Not in Setup",INDEX(Setup!$E$5:$E$34,31-SUMPRODUCT(MAX((Setup!$D$5:$D$34=H18)*(35-ROW(Setup!$D$5:$D$34))))))) | K18: =IF(AND(A18="",C18="",D18="",E18="",F18="",H18=""),"",IF(NOT(ISNUMBER(A18)),"Enter a date",IF(AND(F18<>"",OR(NOT(ISNUMBER(F18)),N(F18)<0)),"Minutes must be a number of 0 or more",IF(G18="","Enter start and end times, or minutes",IF(C18="","Pick a machine",IF(SUMPRODUCT(--(Setup!$A$5:$A$34=C18))=0,"Machine not in Setup",IF(H18="","Pick a reason (counted as unclassified)",IF(I18="Not in Setup","Reason not in Setup (counted as unclassified)",IF(N(G18)=0,"0 minutes: not counted as a stop","OK")))))))))
G19: =IF(F19<>"",IF(AND(ISNUMBER(F19),N(F19)>=0),F19,""),IF(AND(ISNUMBER(D19),ISNUMBER(E19)),ROUND(MOD(E19-D19,1)*1440,0),"")) | I19: =IF(H19="","",IF(SUMPRODUCT(MAX((Setup!$D$5:$D$34=H19)*(35-ROW(Setup!$D$5:$D$34))))=0,"Not in Setup",INDEX(Setup!$E$5:$E$34,31-SUMPRODUCT(MAX((Setup!$D$5:$D$34=H19)*(35-ROW(Setup!$D$5:$D$34))))))) | K19: =IF(AND(A19="",C19="",D19="",E19="",F19="",H19=""),"",IF(NOT(ISNUMBER(A19)),"Enter a date",IF(AND(F19<>"",OR(NOT(ISNUMBER(F19)),N(F19)<0)),"Minutes must be a number of 0 or more",IF(G19="","Enter start and end times, or minutes",IF(C19="","Pick a machine",IF(SUMPRODUCT(--(Setup!$A$5:$A$34=C19))=0,"Machine not in Setup",IF(H19="","Pick a reason (counted as unclassified)",IF(I19="Not in Setup","Reason not in Setup (counted as unclassified)",IF(N(G19)=0,"0 minutes: not counted as a stop","OK")))))))))
G20: =IF(F20<>"",IF(AND(ISNUMBER(F20),N(F20)>=0),F20,""),IF(AND(ISNUMBER(D20),ISNUMBER(E20)),ROUND(MOD(E20-D20,1)*1440,0),"")) | I20: =IF(H20="","",IF(SUMPRODUCT(MAX((Setup!$D$5:$D$34=H20)*(35-ROW(Setup!$D$5:$D$34))))=0,"Not in Setup",INDEX(Setup!$E$5:$E$34,31-SUMPRODUCT(MAX((Setup!$D$5:$D$34=H20)*(35-ROW(Setup!$D$5:$D$34))))))) | K20: =IF(AND(A20="",C20="",D20="",E20="",F20="",H20=""),"",IF(NOT(ISNUMBER(A20)),"Enter a date",IF(AND(F20<>"",OR(NOT(ISNUMBER(F20)),N(F20)<0)),"Minutes must be a number of 0 or more",IF(G20="","Enter start and end times, or minutes",IF(C20="","Pick a machine",IF(SUMPRODUCT(--(Setup!$A$5:$A$34=C20))=0,"Machine not in Setup",IF(H20="","Pick a reason (counted as unclassified)",IF(I20="Not in Setup","Reason not in Setup (counted as unclassified)",IF(N(G20)=0,"0 minutes: not counted as a stop","OK")))))))))
G21: =IF(F21<>"",IF(AND(ISNUMBER(F21),N(F21)>=0),F21,""),IF(AND(ISNUMBER(D21),ISNUMBER(E21)),ROUND(MOD(E21-D21,1)*1440,0),"")) | I21: =IF(H21="","",IF(SUMPRODUCT(MAX((Setup!$D$5:$D$34=H21)*(35-ROW(Setup!$D$5:$D$34))))=0,"Not in Setup",INDEX(Setup!$E$5:$E$34,31-SUMPRODUCT(MAX((Setup!$D$5:$D$34=H21)*(35-ROW(Setup!$D$5:$D$34))))))) | K21: =IF(AND(A21="",C21="",D21="",E21="",F21="",H21=""),"",IF(NOT(ISNUMBER(A21)),"Enter a date",IF(AND(F21<>"",OR(NOT(ISNUMBER(F21)),N(F21)<0)),"Minutes must be a number of 0 or more",IF(G21="","Enter start and end times, or minutes",IF(C21="","Pick a machine",IF(SUMPRODUCT(--(Setup!$A$5:$A$34=C21))=0,"Machine not in Setup",IF(H21="","Pick a reason (counted as unclassified)",IF(I21="Not in Setup","Reason not in Setup (counted as unclassified)",IF(N(G21)=0,"0 minutes: not counted as a stop","OK")))))))))
G22: =IF(F22<>"",IF(AND(ISNUMBER(F22),N(F22)>=0),F22,""),IF(AND(ISNUMBER(D22),ISNUMBER(E22)),ROUND(MOD(E22-D22,1)*1440,0),"")) | I22: =IF(H22="","",IF(SUMPRODUCT(MAX((Setup!$D$5:$D$34=H22)*(35-ROW(Setup!$D$5:$D$34))))=0,"Not in Setup",INDEX(Setup!$E$5:$E$34,31-SUMPRODUCT(MAX((Setup!$D$5:$D$34=H22)*(35-ROW(Setup!$D$5:$D$34))))))) | K22: =IF(AND(A22="",C22="",D22="",E22="",F22="",H22=""),"",IF(NOT(ISNUMBER(A22)),"Enter a date",IF(AND(F22<>"",OR(NOT(ISNUMBER(F22)),N(F22)<0)),"Minutes must be a number of 0 or more",IF(G22="","Enter start and end times, or minutes",IF(C22="","Pick a machine",IF(SUMPRODUCT(--(Setup!$A$5:$A$34=C22))=0,"Machine not in Setup",IF(H22="","Pick a reason (counted as unclassified)",IF(I22="Not in Setup","Reason not in Setup (counted as unclassified)",IF(N(G22)=0,"0 minutes: not counted as a stop","OK")))))))))
G23: =IF(F23<>"",IF(AND(ISNUMBER(F23),N(F23)>=0),F23,""),IF(AND(ISNUMBER(D23),ISNUMBER(E23)),ROUND(MOD(E23-D23,1)*1440,0),"")) | I23: =IF(H23="","",IF(SUMPRODUCT(MAX((Setup!$D$5:$D$34=H23)*(35-ROW(Setup!$D$5:$D$34))))=0,"Not in Setup",INDEX(Setup!$E$5:$E$34,31-SUMPRODUCT(MAX((Setup!$D$5:$D$34=H23)*(35-ROW(Setup!$D$5:$D$34))))))) | K23: =IF(AND(A23="",C23="",D23="",E23="",F23="",H23=""),"",IF(NOT(ISNUMBER(A23)),"Enter a date",IF(AND(F23<>"",OR(NOT(ISNUMBER(F23)),N(F23)<0)),"Minutes must be a number of 0 or more",IF(G23="","Enter start and end times, or minutes",IF(C23="","Pick a machine",IF(SUMPRODUCT(--(Setup!$A$5:$A$34=C23))=0,"Machine not in Setup",IF(H23="","Pick a reason (counted as unclassified)",IF(I23="Not in Setup","Reason not in Setup (counted as unclassified)",IF(N(G23)=0,"0 minutes: not counted as a stop","OK")))))))))
... G1004: =IF(F1004<>"",IF(AND(ISNUMBER(F1004),N(F1004)>=0),F1004,""),IF(AND(ISNUMBER(D1004),ISNUMBER(E1004)),ROUND(MOD(E1004-D1004,1)*1440,0),"")) | I1004: =IF(H1004="","",IF(SUMPRODUCT(MAX((Setup!$D$5:$D$34=H1004)*(35-ROW(Setup!$D$5:$D$34))))=0,"Not in Setup",INDEX(Setup!$E$5:$E$34,31-SUMPRODUCT(MAX((Setup!$D$5:$D$34=H1004)*(35-ROW(Setup!$D$5:$D$34))))))) | K1004: =IF(AND(A1004="",C1004="",D1004="",E1004="",F1004="",H1004=""),"",IF(NOT(ISNUMBER(A1004)),"Enter a date",IF(AND(F1004<>"",OR(NOT(ISNUMBER(F1004)),N(F1004)<0)),"Minutes must be a number of 0 or more",IF(G1004="","Enter start and end times, or minutes",IF(C1004="","Pick a machine",IF(SUMPRODUCT(--(Setup!$A$5:$A$34=C1004))=0,"Machine not in Setup",IF(H1004="","Pick a reason (counted as unclassified)",IF(I1004="Not in Setup","Reason not in Setup (counted as unclassified)",IF(N(G1004)=0,"0 minutes: not counted as a stop","OK")))))))))

Sheet Pareto
A1: Downtime Pareto
A2: Reasons ranked by minutes lost. Leave filters blank to include everything.
A3: From date | D3: =IF(B3="",DATE(1900,1,1),B3) -> 2
A4: To date | D4: =IF(B4="",DATE(2999,12,31),B4) -> 401768
A5: Machine (blank = all)
A6: Total downtime (min) | B6: =SUMPRODUCT(('Downtime Log'!$A$5:$A$1004>=$D$3)*('Downtime Log'!$A$5:$A$1004<=$D$4)*((($B$5="")+('Downtime Log'!$C$5:$C$1004=$B$5))>0),'Downtime Log'!$G$5:$G$1004) -> 255
A7: Unclassified (min) | B7: =B6-SUM($J$9:$J$38) -> 0 | C7: Reason blank or not on Setup. Check the log.
A8: Rank | B8: Reason | C8: Minutes | D8: Stops | E8: % of total | F8: Cumulative % | I8: Helper: reason | J8: Helper: minutes | K8: Helper: stops | L8: Helper: sort key
A9: 1 | B9: =IF(INDEX($J$9:$J$38,MATCH(LARGE($L$9:$L$38,A9),$L$9:$L$38,0))<=0,"",INDEX($I$9:$I$38,MATCH(LARGE($L$9:$L$38,A9),$L$9:$L$38,0))) -> Mechanical breakdown | C9: =IF(B9="","",INDEX($J$9:$J$38,MATCH(LARGE($L$9:$L$38,A9),$L$9:$L$38,0))) -> 100 | D9: =IF(B9="","",INDEX($K$9:$K$38,MATCH(LARGE($L$9:$L$38,A9),$L$9:$L$38,0))) -> 2 | E9: =IF(OR(B9="",$B$6=0),"",C9/$B$6) -> 0.39215686 | F9: =IF(OR(B9="",$B$6=0),"",SUM($C$9:C9)/$B$6) -> 0.39215686 | I9: =IF(Setup!D5="","",IF(SUMPRODUCT(--(Setup!$D$4:D4=Setup!D5))>0,"",Setup!D5)) -> Mechanical breakdown | J9: =IF(I9="",0,SUMPRODUCT(('Downtime Log'!$H$5:$H$1004=I9)*('Downtime Log'!$A$5:$A$1004>=$D$3)*('Downtime Log'!$A$5:$A$1004<=$D$4)*((($B$5="")+('Downtime Log'!$C$5:$C$1004=$B$5))>0),'Downtime Log'!$G$5:$G$1004)) -> 100 | K9: =IF(I9="",0,SUMPRODUCT(('Downtime Log'!$H$5:$H$1004=I9)*('Downtime Log'!$A$5:$A$1004>=$D$3)*('Downtime Log'!$A$5:$A$1004<=$D$4)*((($B$5="")+('Downtime Log'!$C$5:$C$1004=$B$5))>0)*ISNUMBER('Downtime Log'!$G$5:$G$1004)*('Downtime Log'!$G$5:$G$1004>0))) -> 2 | L9: =IF(I9="",-1,J9+(34-1)/1000000) -> 100.00003
A10: 2 | B10: =IF(INDEX($J$9:$J$38,MATCH(LARGE($L$9:$L$38,A10),$L$9:$L$38,0))<=0,"",INDEX($I$9:$I$38,MATCH(LARGE($L$9:$L$38,A10),$L$9:$L$38,0))) -> Changeover / setup | C10: =IF(B10="","",INDEX($J$9:$J$38,MATCH(LARGE($L$9:$L$38,A10),$L$9:$L$38,0))) -> 65 | D10: =IF(B10="","",INDEX($K$9:$K$38,MATCH(LARGE($L$9:$L$38,A10),$L$9:$L$38,0))) -> 2 | E10: =IF(OR(B10="",$B$6=0),"",C10/$B$6) -> 0.25490196 | F10: =IF(OR(B10="",$B$6=0),"",SUM($C$9:C10)/$B$6) -> 0.64705882 | I10: =IF(Setup!D6="","",IF(SUMPRODUCT(--(Setup!$D$4:D5=Setup!D6))>0,"",Setup!D6)) -> Electrical / controls fault | J10: =IF(I10="",0,SUMPRODUCT(('Downtime Log'!$H$5:$H$1004=I10)*('Downtime Log'!$A$5:$A$1004>=$D$3)*('Downtime Log'!$A$5:$A$1004<=$D$4)*((($B$5="")+('Downtime Log'!$C$5:$C$1004=$B$5))>0),'Downtime Log'!$G$5:$G$1004)) -> 0 | K10: =IF(I10="",0,SUMPRODUCT(('Downtime Log'!$H$5:$H$1004=I10)*('Downtime Log'!$A$5:$A$1004>=$D$3)*('Downtime Log'!$A$5:$A$1004<=$D$4)*((($B$5="")+('Downtime Log'!$C$5:$C$1004=$B$5))>0)*ISNUMBER('Downtime Log'!$G$5:$G$1004)*('Downtime Log'!$G$5:$G$1004>0))) -> 0 | L10: =IF(I10="",-1,J10+(34-2)/1000000) -> 3.2e-05
A11: 3 | B11: =IF(INDEX($J$9:$J$38,MATCH(LARGE($L$9:$L$38,A11),$L$9:$L$38,0))<=0,"",INDEX($I$9:$I$38,MATCH(LARGE($L$9:$L$38,A11),$L$9:$L$38,0))) -> Tooling failure | C11: =IF(B11="","",INDEX($J$9:$J$38,MATCH(LARGE($L$9:$L$38,A11),$L$9:$L$38,0))) -> 60 | D11: =IF(B11="","",INDEX($K$9:$K$38,MATCH(LARGE($L$9:$L$38,A11),$L$9:$L$38,0))) -> 1 | E11: =IF(OR(B11="",$B$6=0),"",C11/$B$6) -> 0.23529412 | F11: =IF(OR(B11="",$B$6=0),"",SUM($C$9:C11)/$B$6) -> 0.88235294 | I11: =IF(Setup!D7="","",IF(SUMPRODUCT(--(Setup!$D$4:D6=Setup!D7))>0,"",Setup!D7)) -> Tooling failure | J11: =IF(I11="",0,SUMPRODUCT(('Downtime Log'!$H$5:$H$1004=I11)*('Downtime Log'!$A$5:$A$1004>=$D$3)*('Downtime Log'!$A$5:$A$1004<=$D$4)*((($B$5="")+('Downtime Log'!$C$5:$C$1004=$B$5))>0),'Downtime Log'!$G$5:$G$1004)) -> 60 | K11: =IF(I11="",0,SUMPRODUCT(('Downtime Log'!$H$5:$H$1004=I11)*('Downtime Log'!$A$5:$A$1004>=$D$3)*('Downtime Log'!$A$5:$A$1004<=$D$4)*((($B$5="")+('Downtime Log'!$C$5:$C$1004=$B$5))>0)*ISNUMBER('Downtime Log'!$G$5:$G$1004)*('Downtime Log'!$G$5:$G$1004>0))) -> 1 | L11: =IF(I11="",-1,J11+(34-3)/1000000) -> 60.000031
A12: 4 | B12: =IF(INDEX($J$9:$J$38,MATCH(LARGE($L$9:$L$38,A12),$L$9:$L$38,0))<=0,"",INDEX($I$9:$I$38,MATCH(LARGE($L$9:$L$38,A12),$L$9:$L$38,0))) -> Waiting for material | C12: =IF(B12="","",INDEX($J$9:$J$38,MATCH(LARGE($L$9:$L$38,A12),$L$9:$L$38,0))) -> 15 | D12: =IF(B12="","",INDEX($K$9:$K$38,MATCH(LARGE($L$9:$L$38,A12),$L$9:$L$38,0))) -> 1 | E12: =IF(OR(B12="",$B$6=0),"",C12/$B$6) -> 0.058823529 | F12: =IF(OR(B12="",$B$6=0),"",SUM($C$9:C12)/$B$6) -> 0.94117647 | I12: =IF(Setup!D8="","",IF(SUMPRODUCT(--(Setup!$D$4:D7=Setup!D8))>0,"",Setup!D8)) -> Changeover / setup | J12: =IF(I12="",0,SUMPRODUCT(('Downtime Log'!$H$5:$H$1004=I12)*('Downtime Log'!$A$5:$A$1004>=$D$3)*('Downtime Log'!$A$5:$A$1004<=$D$4)*((($B$5="")+('Downtime Log'!$C$5:$C$1004=$B$5))>0),'Downtime Log'!$G$5:$G$1004)) -> 65 | K12: =IF(I12="",0,SUMPRODUCT(('Downtime Log'!$H$5:$H$1004=I12)*('Downtime Log'!$A$5:$A$1004>=$D$3)*('Downtime Log'!$A$5:$A$1004<=$D$4)*((($B$5="")+('Downtime Log'!$C$5:$C$1004=$B$5))>0)*ISNUMBER('Downtime Log'!$G$5:$G$1004)*('Downtime Log'!$G$5:$G$1004>0))) -> 2 | L12: =IF(I12="",-1,J12+(34-4)/1000000) -> 65.00003
A13: 5 | B13: =IF(INDEX($J$9:$J$38,MATCH(LARGE($L$9:$L$38,A13),$L$9:$L$38,0))<=0,"",INDEX($I$9:$I$38,MATCH(LARGE($L$9:$L$38,A13),$L$9:$L$38,0))) -> Quality hold / inspection | C13: =IF(B13="","",INDEX($J$9:$J$38,MATCH(LARGE($L$9:$L$38,A13),$L$9:$L$38,0))) -> 15 | D13: =IF(B13="","",INDEX($K$9:$K$38,MATCH(LARGE($L$9:$L$38,A13),$L$9:$L$38,0))) -> 1 | E13: =IF(OR(B13="",$B$6=0),"",C13/$B$6) -> 0.058823529 | F13: =IF(OR(B13="",$B$6=0),"",SUM($C$9:C13)/$B$6) -> 1 | I13: =IF(Setup!D9="","",IF(SUMPRODUCT(--(Setup!$D$4:D8=Setup!D9))>0,"",Setup!D9)) -> Adjustment / tuning | J13: =IF(I13="",0,SUMPRODUCT(('Downtime Log'!$H$5:$H$1004=I13)*('Downtime Log'!$A$5:$A$1004>=$D$3)*('Downtime Log'!$A$5:$A$1004<=$D$4)*((($B$5="")+('Downtime Log'!$C$5:$C$1004=$B$5))>0),'Downtime Log'!$G$5:$G$1004)) -> 0 | K13: =IF(I13="",0,SUMPRODUCT(('Downtime Log'!$H$5:$H$1004=I13)*('Downtime Log'!$A$5:$A$1004>=$D$3)*('Downtime Log'!$A$5:$A$1004<=$D$4)*((($B$5="")+('Downtime Log'!$C$5:$C$1004=$B$5))>0)*ISNUMBER('Downtime Log'!$G$5:$G$1004)*('Downtime Log'!$G$5:$G$1004>0))) -> 0 | L13: =IF(I13="",-1,J13+(34-5)/1000000) -> 2.9e-05
A14: 6 | B14: =IF(INDEX($J$9:$J$38,MATCH(LARGE($L$9:$L$38,A14),$L$9:$L$38,0))<=0,"",INDEX($I$9:$I$38,MATCH(LARGE($L$9:$L$38,A14),$L$9:$L$38,0))) | C14: =IF(B14="","",INDEX($J$9:$J$38,MATCH(LARGE($L$9:$L$38,A14),$L$9:$L$38,0))) | D14: =IF(B14="","",INDEX($K$9:$K$38,MATCH(LARGE($L$9:$L$38,A14),$L$9:$L$38,0))) | E14: =IF(OR(B14="",$B$6=0),"",C14/$B$6) | F14: =IF(OR(B14="",$B$6=0),"",SUM($C$9:C14)/$B$6) | I14: =IF(Setup!D10="","",IF(SUMPRODUCT(--(Setup!$D$4:D9=Setup!D10))>0,"",Setup!D10)) -> Waiting for material | J14: =IF(I14="",0,SUMPRODUCT(('Downtime Log'!$H$5:$H$1004=I14)*('Downtime Log'!$A$5:$A$1004>=$D$3)*('Downtime Log'!$A$5:$A$1004<=$D$4)*((($B$5="")+('Downtime Log'!$C$5:$C$1004=$B$5))>0),'Downtime Log'!$G$5:$G$1004)) -> 15 | K14: =IF(I14="",0,SUMPRODUCT(('Downtime Log'!$H$5:$H$1004=I14)*('Downtime Log'!$A$5:$A$1004>=$D$3)*('Downtime Log'!$A$5:$A$1004<=$D$4)*((($B$5="")+('Downtime Log'!$C$5:$C$1004=$B$5))>0)*ISNUMBER('Downtime Log'!$G$5:$G$1004)*('Downtime Log'!$G$5:$G$1004>0))) -> 1 | L14: =IF(I14="",-1,J14+(34-6)/1000000) -> 15.000028
A15: 7 | B15: =IF(INDEX($J$9:$J$38,MATCH(LARGE($L$9:$L$38,A15),$L$9:$L$38,0))<=0,"",INDEX($I$9:$I$38,MATCH(LARGE($L$9:$L$38,A15),$L$9:$L$38,0))) | C15: =IF(B15="","",INDEX($J$9:$J$38,MATCH(LARGE($L$9:$L$38,A15),$L$9:$L$38,0))) | D15: =IF(B15="","",INDEX($K$9:$K$38,MATCH(LARGE($L$9:$L$38,A15),$L$9:$L$38,0))) | E15: =IF(OR(B15="",$B$6=0),"",C15/$B$6) | F15: =IF(OR(B15="",$B$6=0),"",SUM($C$9:C15)/$B$6) | I15: =IF(Setup!D11="","",IF(SUMPRODUCT(--(Setup!$D$4:D10=Setup!D11))>0,"",Setup!D11)) -> Waiting for upstream process | J15: =IF(I15="",0,SUMPRODUCT(('Downtime Log'!$H$5:$H$1004=I15)*('Downtime Log'!$A$5:$A$1004>=$D$3)*('Downtime Log'!$A$5:$A$1004<=$D$4)*((($B$5="")+('Downtime Log'!$C$5:$C$1004=$B$5))>0),'Downtime Log'!$G$5:$G$1004)) -> 0 | K15: =IF(I15="",0,SUMPRODUCT(('Downtime Log'!$H$5:$H$1004=I15)*('Downtime Log'!$A$5:$A$1004>=$D$3)*('Downtime Log'!$A$5:$A$1004<=$D$4)*((($B$5="")+('Downtime Log'!$C$5:$C$1004=$B$5))>0)*ISNUMBER('Downtime Log'!$G$5:$G$1004)*('Downtime Log'!$G$5:$G$1004>0))) -> 0 | L15: =IF(I15="",-1,J15+(34-7)/1000000) -> 2.7e-05
A16: 8 | B16: =IF(INDEX($J$9:$J$38,MATCH(LARGE($L$9:$L$38,A16),$L$9:$L$38,0))<=0,"",INDEX($I$9:$I$38,MATCH(LARGE($L$9:$L$38,A16),$L$9:$L$38,0))) | C16: =IF(B16="","",INDEX($J$9:$J$38,MATCH(LARGE($L$9:$L$38,A16),$L$9:$L$38,0))) | D16: =IF(B16="","",INDEX($K$9:$K$38,MATCH(LARGE($L$9:$L$38,A16),$L$9:$L$38,0))) | E16: =IF(OR(B16="",$B$6=0),"",C16/$B$6) | F16: =IF(OR(B16="",$B$6=0),"",SUM($C$9:C16)/$B$6) | I16: =IF(Setup!D12="","",IF(SUMPRODUCT(--(Setup!$D$4:D11=Setup!D12))>0,"",Setup!D12)) -> Quality hold / inspection | J16: =IF(I16="",0,SUMPRODUCT(('Downtime Log'!$H$5:$H$1004=I16)*('Downtime Log'!$A$5:$A$1004>=$D$3)*('Downtime Log'!$A$5:$A$1004<=$D$4)*((($B$5="")+('Downtime Log'!$C$5:$C$1004=$B$5))>0),'Downtime Log'!$G$5:$G$1004)) -> 15 | K16: =IF(I16="",0,SUMPRODUCT(('Downtime Log'!$H$5:$H$1004=I16)*('Downtime Log'!$A$5:$A$1004>=$D$3)*('Downtime Log'!$A$5:$A$1004<=$D$4)*((($B$5="")+('Downtime Log'!$C$5:$C$1004=$B$5))>0)*ISNUMBER('Downtime Log'!$G$5:$G$1004)*('Downtime Log'!$G$5:$G$1004>0))) -> 1 | L16: =IF(I16="",-1,J16+(34-8)/1000000) -> 15.000026
A17: 9 | B17: =IF(INDEX($J$9:$J$38,MATCH(LARGE($L$9:$L$38,A17),$L$9:$L$38,0))<=0,"",INDEX($I$9:$I$38,MATCH(LARGE($L$9:$L$38,A17),$L$9:$L$38,0))) | C17: =IF(B17="","",INDEX($J$9:$J$38,MATCH(LARGE($L$9:$L$38,A17),$L$9:$L$38,0))) | D17: =IF(B17="","",INDEX($K$9:$K$38,MATCH(LARGE($L$9:$L$38,A17),$L$9:$L$38,0))) | E17: =IF(OR(B17="",$B$6=0),"",C17/$B$6) | F17: =IF(OR(B17="",$B$6=0),"",SUM($C$9:C17)/$B$6) | I17: =IF(Setup!D13="","",IF(SUMPRODUCT(--(Setup!$D$4:D12=Setup!D13))>0,"",Setup!D13)) -> No operator available | J17: =IF(I17="",0,SUMPRODUCT(('Downtime Log'!$H$5:$H$1004=I17)*('Downtime Log'!$A$5:$A$1004>=$D$3)*('Downtime Log'!$A$5:$A$1004<=$D$4)*((($B$5="")+('Downtime Log'!$C$5:$C$1004=$B$5))>0),'Downtime Log'!$G$5:$G$1004)) -> 0 | K17: =IF(I17="",0,SUMPRODUCT(('Downtime Log'!$H$5:$H$1004=I17)*('Downtime Log'!$A$5:$A$1004>=$D$3)*('Downtime Log'!$A$5:$A$1004<=$D$4)*((($B$5="")+('Downtime Log'!$C$5:$C$1004=$B$5))>0)*ISNUMBER('Downtime Log'!$G$5:$G$1004)*('Downtime Log'!$G$5:$G$1004>0))) -> 0 | L17: =IF(I17="",-1,J17+(34-9)/1000000) -> 2.5e-05
A18: 10 | B18: =IF(INDEX($J$9:$J$38,MATCH(LARGE($L$9:$L$38,A18),$L$9:$L$38,0))<=0,"",INDEX($I$9:$I$38,MATCH(LARGE($L$9:$L$38,A18),$L$9:$L$38,0))) | C18: =IF(B18="","",INDEX($J$9:$J$38,MATCH(LARGE($L$9:$L$38,A18),$L$9:$L$38,0))) | D18: =IF(B18="","",INDEX($K$9:$K$38,MATCH(LARGE($L$9:$L$38,A18),$L$9:$L$38,0))) | E18: =IF(OR(B18="",$B$6=0),"",C18/$B$6) | F18: =IF(OR(B18="",$B$6=0),"",SUM($C$9:C18)/$B$6) | I18: =IF(Setup!D14="","",IF(SUMPRODUCT(--(Setup!$D$4:D13=Setup!D14))>0,"",Setup!D14)) -> Planned maintenance | J18: =IF(I18="",0,SUMPRODUCT(('Downtime Log'!$H$5:$H$1004=I18)*('Downtime Log'!$A$5:$A$1004>=$D$3)*('Downtime Log'!$A$5:$A$1004<=$D$4)*((($B$5="")+('Downtime Log'!$C$5:$C$1004=$B$5))>0),'Downtime Log'!$G$5:$G$1004)) -> 0 | K18: =IF(I18="",0,SUMPRODUCT(('Downtime Log'!$H$5:$H$1004=I18)*('Downtime Log'!$A$5:$A$1004>=$D$3)*('Downtime Log'!$A$5:$A$1004<=$D$4)*((($B$5="")+('Downtime Log'!$C$5:$C$1004=$B$5))>0)*ISNUMBER('Downtime Log'!$G$5:$G$1004)*('Downtime Log'!$G$5:$G$1004>0))) -> 0 | L18: =IF(I18="",-1,J18+(34-10)/1000000) -> 2.4e-05
A19: 11 | B19: =IF(INDEX($J$9:$J$38,MATCH(LARGE($L$9:$L$38,A19),$L$9:$L$38,0))<=0,"",INDEX($I$9:$I$38,MATCH(LARGE($L$9:$L$38,A19),$L$9:$L$38,0))) | C19: =IF(B19="","",INDEX($J$9:$J$38,MATCH(LARGE($L$9:$L$38,A19),$L$9:$L$38,0))) | D19: =IF(B19="","",INDEX($K$9:$K$38,MATCH(LARGE($L$9:$L$38,A19),$L$9:$L$38,0))) | E19: =IF(OR(B19="",$B$6=0),"",C19/$B$6) | F19: =IF(OR(B19="",$B$6=0),"",SUM($C$9:C19)/$B$6) | I19: =IF(Setup!D15="","",IF(SUMPRODUCT(--(Setup!$D$4:D14=Setup!D15))>0,"",Setup!D15)) -> Meeting / training | J19: =IF(I19="",0,SUMPRODUCT(('Downtime Log'!$H$5:$H$1004=I19)*('Downtime Log'!$A$5:$A$1004>=$D$3)*('Downtime Log'!$A$5:$A$1004<=$D$4)*((($B$5="")+('Downtime Log'!$C$5:$C$1004=$B$5))>0),'Downtime Log'!$G$5:$G$1004)) -> 0 | K19: =IF(I19="",0,SUMPRODUCT(('Downtime Log'!$H$5:$H$1004=I19)*('Downtime Log'!$A$5:$A$1004>=$D$3)*('Downtime Log'!$A$5:$A$1004<=$D$4)*((($B$5="")+('Downtime Log'!$C$5:$C$1004=$B$5))>0)*ISNUMBER('Downtime Log'!$G$5:$G$1004)*('Downtime Log'!$G$5:$G$1004>0))) -> 0 | L19: =IF(I19="",-1,J19+(34-11)/1000000) -> 2.3e-05
A20: 12 | B20: =IF(INDEX($J$9:$J$38,MATCH(LARGE($L$9:$L$38,A20),$L$9:$L$38,0))<=0,"",INDEX($I$9:$I$38,MATCH(LARGE($L$9:$L$38,A20),$L$9:$L$38,0))) | C20: =IF(B20="","",INDEX($J$9:$J$38,MATCH(LARGE($L$9:$L$38,A20),$L$9:$L$38,0))) | D20: =IF(B20="","",INDEX($K$9:$K$38,MATCH(LARGE($L$9:$L$38,A20),$L$9:$L$38,0))) | E20: =IF(OR(B20="",$B$6=0),"",C20/$B$6) | F20: =IF(OR(B20="",$B$6=0),"",SUM($C$9:C20)/$B$6) | I20: =IF(Setup!D16="","",IF(SUMPRODUCT(--(Setup!$D$4:D15=Setup!D16))>0,"",Setup!D16)) -> Other (describe in notes) | J20: =IF(I20="",0,SUMPRODUCT(('Downtime Log'!$H$5:$H$1004=I20)*('Downtime Log'!$A$5:$A$1004>=$D$3)*('Downtime Log'!$A$5:$A$1004<=$D$4)*((($B$5="")+('Downtime Log'!$C$5:$C$1004=$B$5))>0),'Downtime Log'!$G$5:$G$1004)) -> 0 | K20: =IF(I20="",0,SUMPRODUCT(('Downtime Log'!$H$5:$H$1004=I20)*('Downtime Log'!$A$5:$A$1004>=$D$3)*('Downtime Log'!$A$5:$A$1004<=$D$4)*((($B$5="")+('Downtime Log'!$C$5:$C$1004=$B$5))>0)*ISNUMBER('Downtime Log'!$G$5:$G$1004)*('Downtime Log'!$G$5:$G$1004>0))) -> 0 | L20: =IF(I20="",-1,J20+(34-12)/1000000) -> 2.2e-05
A21: 13 | B21: =IF(INDEX($J$9:$J$38,MATCH(LARGE($L$9:$L$38,A21),$L$9:$L$38,0))<=0,"",INDEX($I$9:$I$38,MATCH(LARGE($L$9:$L$38,A21),$L$9:$L$38,0))) | C21: =IF(B21="","",INDEX($J$9:$J$38,MATCH(LARGE($L$9:$L$38,A21),$L$9:$L$38,0))) | D21: =IF(B21="","",INDEX($K$9:$K$38,MATCH(LARGE($L$9:$L$38,A21),$L$9:$L$38,0))) | E21: =IF(OR(B21="",$B$6=0),"",C21/$B$6) | F21: =IF(OR(B21="",$B$6=0),"",SUM($C$9:C21)/$B$6) | I21: =IF(Setup!D17="","",IF(SUMPRODUCT(--(Setup!$D$4:D16=Setup!D17))>0,"",Setup!D17)) | J21: =IF(I21="",0,SUMPRODUCT(('Downtime Log'!$H$5:$H$1004=I21)*('Downtime Log'!$A$5:$A$1004>=$D$3)*('Downtime Log'!$A$5:$A$1004<=$D$4)*((($B$5="")+('Downtime Log'!$C$5:$C$1004=$B$5))>0),'Downtime Log'!$G$5:$G$1004)) -> 0 | K21: =IF(I21="",0,SUMPRODUCT(('Downtime Log'!$H$5:$H$1004=I21)*('Downtime Log'!$A$5:$A$1004>=$D$3)*('Downtime Log'!$A$5:$A$1004<=$D$4)*((($B$5="")+('Downtime Log'!$C$5:$C$1004=$B$5))>0)*ISNUMBER('Downtime Log'!$G$5:$G$1004)*('Downtime Log'!$G$5:$G$1004>0))) -> 0 | L21: =IF(I21="",-1,J21+(34-13)/1000000) -> -1
A22: 14 | B22: =IF(INDEX($J$9:$J$38,MATCH(LARGE($L$9:$L$38,A22),$L$9:$L$38,0))<=0,"",INDEX($I$9:$I$38,MATCH(LARGE($L$9:$L$38,A22),$L$9:$L$38,0))) | C22: =IF(B22="","",INDEX($J$9:$J$38,MATCH(LARGE($L$9:$L$38,A22),$L$9:$L$38,0))) | D22: =IF(B22="","",INDEX($K$9:$K$38,MATCH(LARGE($L$9:$L$38,A22),$L$9:$L$38,0))) | E22: =IF(OR(B22="",$B$6=0),"",C22/$B$6) | F22: =IF(OR(B22="",$B$6=0),"",SUM($C$9:C22)/$B$6) | I22: =IF(Setup!D18="","",IF(SUMPRODUCT(--(Setup!$D$4:D17=Setup!D18))>0,"",Setup!D18)) | J22: =IF(I22="",0,SUMPRODUCT(('Downtime Log'!$H$5:$H$1004=I22)*('Downtime Log'!$A$5:$A$1004>=$D$3)*('Downtime Log'!$A$5:$A$1004<=$D$4)*((($B$5="")+('Downtime Log'!$C$5:$C$1004=$B$5))>0),'Downtime Log'!$G$5:$G$1004)) -> 0 | K22: =IF(I22="",0,SUMPRODUCT(('Downtime Log'!$H$5:$H$1004=I22)*('Downtime Log'!$A$5:$A$1004>=$D$3)*('Downtime Log'!$A$5:$A$1004<=$D$4)*((($B$5="")+('Downtime Log'!$C$5:$C$1004=$B$5))>0)*ISNUMBER('Downtime Log'!$G$5:$G$1004)*('Downtime Log'!$G$5:$G$1004>0))) -> 0 | L22: =IF(I22="",-1,J22+(34-14)/1000000) -> -1
A23: 15 | B23: =IF(INDEX($J$9:$J$38,MATCH(LARGE($L$9:$L$38,A23),$L$9:$L$38,0))<=0,"",INDEX($I$9:$I$38,MATCH(LARGE($L$9:$L$38,A23),$L$9:$L$38,0))) | C23: =IF(B23="","",INDEX($J$9:$J$38,MATCH(LARGE($L$9:$L$38,A23),$L$9:$L$38,0))) | D23: =IF(B23="","",INDEX($K$9:$K$38,MATCH(LARGE($L$9:$L$38,A23),$L$9:$L$38,0))) | E23: =IF(OR(B23="",$B$6=0),"",C23/$B$6) | F23: =IF(OR(B23="",$B$6=0),"",SUM($C$9:C23)/$B$6) | I23: =IF(Setup!D19="","",IF(SUMPRODUCT(--(Setup!$D$4:D18=Setup!D19))>0,"",Setup!D19)) | J23: =IF(I23="",0,SUMPRODUCT(('Downtime Log'!$H$5:$H$1004=I23)*('Downtime Log'!$A$5:$A$1004>=$D$3)*('Downtime Log'!$A$5:$A$1004<=$D$4)*((($B$5="")+('Downtime Log'!$C$5:$C$1004=$B$5))>0),'Downtime Log'!$G$5:$G$1004)) -> 0 | K23: =IF(I23="",0,SUMPRODUCT(('Downtime Log'!$H$5:$H$1004=I23)*('Downtime Log'!$A$5:$A$1004>=$D$3)*('Downtime Log'!$A$5:$A$1004<=$D$4)*((($B$5="")+('Downtime Log'!$C$5:$C$1004=$B$5))>0)*ISNUMBER('Downtime Log'!$G$5:$G$1004)*('Downtime Log'!$G$5:$G$1004>0))) -> 0 | L23: =IF(I23="",-1,J23+(34-15)/1000000) -> -1
A24: 16 | B24: =IF(INDEX($J$9:$J$38,MATCH(LARGE($L$9:$L$38,A24),$L$9:$L$38,0))<=0,"",INDEX($I$9:$I$38,MATCH(LARGE($L$9:$L$38,A24),$L$9:$L$38,0))) | C24: =IF(B24="","",INDEX($J$9:$J$38,MATCH(LARGE($L$9:$L$38,A24),$L$9:$L$38,0))) | D24: =IF(B24="","",INDEX($K$9:$K$38,MATCH(LARGE($L$9:$L$38,A24),$L$9:$L$38,0))) | E24: =IF(OR(B24="",$B$6=0),"",C24/$B$6) | F24: =IF(OR(B24="",$B$6=0),"",SUM($C$9:C24)/$B$6) | I24: =IF(Setup!D20="","",IF(SUMPRODUCT(--(Setup!$D$4:D19=Setup!D20))>0,"",Setup!D20)) | J24: =IF(I24="",0,SUMPRODUCT(('Downtime Log'!$H$5:$H$1004=I24)*('Downtime Log'!$A$5:$A$1004>=$D$3)*('Downtime Log'!$A$5:$A$1004<=$D$4)*((($B$5="")+('Downtime Log'!$C$5:$C$1004=$B$5))>0),'Downtime Log'!$G$5:$G$1004)) -> 0 | K24: =IF(I24="",0,SUMPRODUCT(('Downtime Log'!$H$5:$H$1004=I24)*('Downtime Log'!$A$5:$A$1004>=$D$3)*('Downtime Log'!$A$5:$A$1004<=$D$4)*((($B$5="")+('Downtime Log'!$C$5:$C$1004=$B$5))>0)*ISNUMBER('Downtime Log'!$G$5:$G$1004)*('Downtime Log'!$G$5:$G$1004>0))) -> 0 | L24: =IF(I24="",-1,J24+(34-16)/1000000) -> -1
A25: 17 | B25: =IF(INDEX($J$9:$J$38,MATCH(LARGE($L$9:$L$38,A25),$L$9:$L$38,0))<=0,"",INDEX($I$9:$I$38,MATCH(LARGE($L$9:$L$38,A25),$L$9:$L$38,0))) | C25: =IF(B25="","",INDEX($J$9:$J$38,MATCH(LARGE($L$9:$L$38,A25),$L$9:$L$38,0))) | D25: =IF(B25="","",INDEX($K$9:$K$38,MATCH(LARGE($L$9:$L$38,A25),$L$9:$L$38,0))) | E25: =IF(OR(B25="",$B$6=0),"",C25/$B$6) | F25: =IF(OR(B25="",$B$6=0),"",SUM($C$9:C25)/$B$6) | I25: =IF(Setup!D21="","",IF(SUMPRODUCT(--(Setup!$D$4:D20=Setup!D21))>0,"",Setup!D21)) | J25: =IF(I25="",0,SUMPRODUCT(('Downtime Log'!$H$5:$H$1004=I25)*('Downtime Log'!$A$5:$A$1004>=$D$3)*('Downtime Log'!$A$5:$A$1004<=$D$4)*((($B$5="")+('Downtime Log'!$C$5:$C$1004=$B$5))>0),'Downtime Log'!$G$5:$G$1004)) -> 0 | K25: =IF(I25="",0,SUMPRODUCT(('Downtime Log'!$H$5:$H$1004=I25)*('Downtime Log'!$A$5:$A$1004>=$D$3)*('Downtime Log'!$A$5:$A$1004<=$D$4)*((($B$5="")+('Downtime Log'!$C$5:$C$1004=$B$5))>0)*ISNUMBER('Downtime Log'!$G$5:$G$1004)*('Downtime Log'!$G$5:$G$1004>0))) -> 0 | L25: =IF(I25="",-1,J25+(34-17)/1000000) -> -1
A26: 18 | B26: =IF(INDEX($J$9:$J$38,MATCH(LARGE($L$9:$L$38,A26),$L$9:$L$38,0))<=0,"",INDEX($I$9:$I$38,MATCH(LARGE($L$9:$L$38,A26),$L$9:$L$38,0))) | C26: =IF(B26="","",INDEX($J$9:$J$38,MATCH(LARGE($L$9:$L$38,A26),$L$9:$L$38,0))) | D26: =IF(B26="","",INDEX($K$9:$K$38,MATCH(LARGE($L$9:$L$38,A26),$L$9:$L$38,0))) | E26: =IF(OR(B26="",$B$6=0),"",C26/$B$6) | F26: =IF(OR(B26="",$B$6=0),"",SUM($C$9:C26)/$B$6) | I26: =IF(Setup!D22="","",IF(SUMPRODUCT(--(Setup!$D$4:D21=Setup!D22))>0,"",Setup!D22)) | J26: =IF(I26="",0,SUMPRODUCT(('Downtime Log'!$H$5:$H$1004=I26)*('Downtime Log'!$A$5:$A$1004>=$D$3)*('Downtime Log'!$A$5:$A$1004<=$D$4)*((($B$5="")+('Downtime Log'!$C$5:$C$1004=$B$5))>0),'Downtime Log'!$G$5:$G$1004)) -> 0 | K26: =IF(I26="",0,SUMPRODUCT(('Downtime Log'!$H$5:$H$1004=I26)*('Downtime Log'!$A$5:$A$1004>=$D$3)*('Downtime Log'!$A$5:$A$1004<=$D$4)*((($B$5="")+('Downtime Log'!$C$5:$C$1004=$B$5))>0)*ISNUMBER('Downtime Log'!$G$5:$G$1004)*('Downtime Log'!$G$5:$G$1004>0))) -> 0 | L26: =IF(I26="",-1,J26+(34-18)/1000000) -> -1
A27: 19 | B27: =IF(INDEX($J$9:$J$38,MATCH(LARGE($L$9:$L$38,A27),$L$9:$L$38,0))<=0,"",INDEX($I$9:$I$38,MATCH(LARGE($L$9:$L$38,A27),$L$9:$L$38,0))) | C27: =IF(B27="","",INDEX($J$9:$J$38,MATCH(LARGE($L$9:$L$38,A27),$L$9:$L$38,0))) | D27: =IF(B27="","",INDEX($K$9:$K$38,MATCH(LARGE($L$9:$L$38,A27),$L$9:$L$38,0))) | E27: =IF(OR(B27="",$B$6=0),"",C27/$B$6) | F27: =IF(OR(B27="",$B$6=0),"",SUM($C$9:C27)/$B$6) | I27: =IF(Setup!D23="","",IF(SUMPRODUCT(--(Setup!$D$4:D22=Setup!D23))>0,"",Setup!D23)) | J27: =IF(I27="",0,SUMPRODUCT(('Downtime Log'!$H$5:$H$1004=I27)*('Downtime Log'!$A$5:$A$1004>=$D$3)*('Downtime Log'!$A$5:$A$1004<=$D$4)*((($B$5="")+('Downtime Log'!$C$5:$C$1004=$B$5))>0),'Downtime Log'!$G$5:$G$1004)) -> 0 | K27: =IF(I27="",0,SUMPRODUCT(('Downtime Log'!$H$5:$H$1004=I27)*('Downtime Log'!$A$5:$A$1004>=$D$3)*('Downtime Log'!$A$5:$A$1004<=$D$4)*((($B$5="")+('Downtime Log'!$C$5:$C$1004=$B$5))>0)*ISNUMBER('Downtime Log'!$G$5:$G$1004)*('Downtime Log'!$G$5:$G$1004>0))) -> 0 | L27: =IF(I27="",-1,J27+(34-19)/1000000) -> -1
A28: 20 | B28: =IF(INDEX($J$9:$J$38,MATCH(LARGE($L$9:$L$38,A28),$L$9:$L$38,0))<=0,"",INDEX($I$9:$I$38,MATCH(LARGE($L$9:$L$38,A28),$L$9:$L$38,0))) | C28: =IF(B28="","",INDEX($J$9:$J$38,MATCH(LARGE($L$9:$L$38,A28),$L$9:$L$38,0))) | D28: =IF(B28="","",INDEX($K$9:$K$38,MATCH(LARGE($L$9:$L$38,A28),$L$9:$L$38,0))) | E28: =IF(OR(B28="",$B$6=0),"",C28/$B$6) | F28: =IF(OR(B28="",$B$6=0),"",SUM($C$9:C28)/$B$6) | I28: =IF(Setup!D24="","",IF(SUMPRODUCT(--(Setup!$D$4:D23=Setup!D24))>0,"",Setup!D24)) | J28: =IF(I28="",0,SUMPRODUCT(('Downtime Log'!$H$5:$H$1004=I28)*('Downtime Log'!$A$5:$A$1004>=$D$3)*('Downtime Log'!$A$5:$A$1004<=$D$4)*((($B$5="")+('Downtime Log'!$C$5:$C$1004=$B$5))>0),'Downtime Log'!$G$5:$G$1004)) -> 0 | K28: =IF(I28="",0,SUMPRODUCT(('Downtime Log'!$H$5:$H$1004=I28)*('Downtime Log'!$A$5:$A$1004>=$D$3)*('Downtime Log'!$A$5:$A$1004<=$D$4)*((($B$5="")+('Downtime Log'!$C$5:$C$1004=$B$5))>0)*ISNUMBER('Downtime Log'!$G$5:$G$1004)*('Downtime Log'!$G$5:$G$1004>0))) -> 0 | L28: =IF(I28="",-1,J28+(34-20)/1000000) -> -1
A29: 21 | B29: =IF(INDEX($J$9:$J$38,MATCH(LARGE($L$9:$L$38,A29),$L$9:$L$38,0))<=0,"",INDEX($I$9:$I$38,MATCH(LARGE($L$9:$L$38,A29),$L$9:$L$38,0))) | C29: =IF(B29="","",INDEX($J$9:$J$38,MATCH(LARGE($L$9:$L$38,A29),$L$9:$L$38,0))) | D29: =IF(B29="","",INDEX($K$9:$K$38,MATCH(LARGE($L$9:$L$38,A29),$L$9:$L$38,0))) | E29: =IF(OR(B29="",$B$6=0),"",C29/$B$6) | F29: =IF(OR(B29="",$B$6=0),"",SUM($C$9:C29)/$B$6) | I29: =IF(Setup!D25="","",IF(SUMPRODUCT(--(Setup!$D$4:D24=Setup!D25))>0,"",Setup!D25)) | J29: =IF(I29="",0,SUMPRODUCT(('Downtime Log'!$H$5:$H$1004=I29)*('Downtime Log'!$A$5:$A$1004>=$D$3)*('Downtime Log'!$A$5:$A$1004<=$D$4)*((($B$5="")+('Downtime Log'!$C$5:$C$1004=$B$5))>0),'Downtime Log'!$G$5:$G$1004)) -> 0 | K29: =IF(I29="",0,SUMPRODUCT(('Downtime Log'!$H$5:$H$1004=I29)*('Downtime Log'!$A$5:$A$1004>=$D$3)*('Downtime Log'!$A$5:$A$1004<=$D$4)*((($B$5="")+('Downtime Log'!$C$5:$C$1004=$B$5))>0)*ISNUMBER('Downtime Log'!$G$5:$G$1004)*('Downtime Log'!$G$5:$G$1004>0))) -> 0 | L29: =IF(I29="",-1,J29+(34-21)/1000000) -> -1
A30: 22 | B30: =IF(INDEX($J$9:$J$38,MATCH(LARGE($L$9:$L$38,A30),$L$9:$L$38,0))<=0,"",INDEX($I$9:$I$38,MATCH(LARGE($L$9:$L$38,A30),$L$9:$L$38,0))) | C30: =IF(B30="","",INDEX($J$9:$J$38,MATCH(LARGE($L$9:$L$38,A30),$L$9:$L$38,0))) | D30: =IF(B30="","",INDEX($K$9:$K$38,MATCH(LARGE($L$9:$L$38,A30),$L$9:$L$38,0))) | E30: =IF(OR(B30="",$B$6=0),"",C30/$B$6) | F30: =IF(OR(B30="",$B$6=0),"",SUM($C$9:C30)/$B$6) | I30: =IF(Setup!D26="","",IF(SUMPRODUCT(--(Setup!$D$4:D25=Setup!D26))>0,"",Setup!D26)) | J30: =IF(I30="",0,SUMPRODUCT(('Downtime Log'!$H$5:$H$1004=I30)*('Downtime Log'!$A$5:$A$1004>=$D$3)*('Downtime Log'!$A$5:$A$1004<=$D$4)*((($B$5="")+('Downtime Log'!$C$5:$C$1004=$B$5))>0),'Downtime Log'!$G$5:$G$1004)) -> 0 | K30: =IF(I30="",0,SUMPRODUCT(('Downtime Log'!$H$5:$H$1004=I30)*('Downtime Log'!$A$5:$A$1004>=$D$3)*('Downtime Log'!$A$5:$A$1004<=$D$4)*((($B$5="")+('Downtime Log'!$C$5:$C$1004=$B$5))>0)*ISNUMBER('Downtime Log'!$G$5:$G$1004)*('Downtime Log'!$G$5:$G$1004>0))) -> 0 | L30: =IF(I30="",-1,J30+(34-22)/1000000) -> -1
A31: 23 | B31: =IF(INDEX($J$9:$J$38,MATCH(LARGE($L$9:$L$38,A31),$L$9:$L$38,0))<=0,"",INDEX($I$9:$I$38,MATCH(LARGE($L$9:$L$38,A31),$L$9:$L$38,0))) | C31: =IF(B31="","",INDEX($J$9:$J$38,MATCH(LARGE($L$9:$L$38,A31),$L$9:$L$38,0))) | D31: =IF(B31="","",INDEX($K$9:$K$38,MATCH(LARGE($L$9:$L$38,A31),$L$9:$L$38,0))) | E31: =IF(OR(B31="",$B$6=0),"",C31/$B$6) | F31: =IF(OR(B31="",$B$6=0),"",SUM($C$9:C31)/$B$6) | I31: =IF(Setup!D27="","",IF(SUMPRODUCT(--(Setup!$D$4:D26=Setup!D27))>0,"",Setup!D27)) | J31: =IF(I31="",0,SUMPRODUCT(('Downtime Log'!$H$5:$H$1004=I31)*('Downtime Log'!$A$5:$A$1004>=$D$3)*('Downtime Log'!$A$5:$A$1004<=$D$4)*((($B$5="")+('Downtime Log'!$C$5:$C$1004=$B$5))>0),'Downtime Log'!$G$5:$G$1004)) -> 0 | K31: =IF(I31="",0,SUMPRODUCT(('Downtime Log'!$H$5:$H$1004=I31)*('Downtime Log'!$A$5:$A$1004>=$D$3)*('Downtime Log'!$A$5:$A$1004<=$D$4)*((($B$5="")+('Downtime Log'!$C$5:$C$1004=$B$5))>0)*ISNUMBER('Downtime Log'!$G$5:$G$1004)*('Downtime Log'!$G$5:$G$1004>0))) -> 0 | L31: =IF(I31="",-1,J31+(34-23)/1000000) -> -1
A32: 24 | B32: =IF(INDEX($J$9:$J$38,MATCH(LARGE($L$9:$L$38,A32),$L$9:$L$38,0))<=0,"",INDEX($I$9:$I$38,MATCH(LARGE($L$9:$L$38,A32),$L$9:$L$38,0))) | C32: =IF(B32="","",INDEX($J$9:$J$38,MATCH(LARGE($L$9:$L$38,A32),$L$9:$L$38,0))) | D32: =IF(B32="","",INDEX($K$9:$K$38,MATCH(LARGE($L$9:$L$38,A32),$L$9:$L$38,0))) | E32: =IF(OR(B32="",$B$6=0),"",C32/$B$6) | F32: =IF(OR(B32="",$B$6=0),"",SUM($C$9:C32)/$B$6) | I32: =IF(Setup!D28="","",IF(SUMPRODUCT(--(Setup!$D$4:D27=Setup!D28))>0,"",Setup!D28)) | J32: =IF(I32="",0,SUMPRODUCT(('Downtime Log'!$H$5:$H$1004=I32)*('Downtime Log'!$A$5:$A$1004>=$D$3)*('Downtime Log'!$A$5:$A$1004<=$D$4)*((($B$5="")+('Downtime Log'!$C$5:$C$1004=$B$5))>0),'Downtime Log'!$G$5:$G$1004)) -> 0 | K32: =IF(I32="",0,SUMPRODUCT(('Downtime Log'!$H$5:$H$1004=I32)*('Downtime Log'!$A$5:$A$1004>=$D$3)*('Downtime Log'!$A$5:$A$1004<=$D$4)*((($B$5="")+('Downtime Log'!$C$5:$C$1004=$B$5))>0)*ISNUMBER('Downtime Log'!$G$5:$G$1004)*('Downtime Log'!$G$5:$G$1004>0))) -> 0 | L32: =IF(I32="",-1,J32+(34-24)/1000000) -> -1
A33: 25 | B33: =IF(INDEX($J$9:$J$38,MATCH(LARGE($L$9:$L$38,A33),$L$9:$L$38,0))<=0,"",INDEX($I$9:$I$38,MATCH(LARGE($L$9:$L$38,A33),$L$9:$L$38,0))) | C33: =IF(B33="","",INDEX($J$9:$J$38,MATCH(LARGE($L$9:$L$38,A33),$L$9:$L$38,0))) | D33: =IF(B33="","",INDEX($K$9:$K$38,MATCH(LARGE($L$9:$L$38,A33),$L$9:$L$38,0))) | E33: =IF(OR(B33="",$B$6=0),"",C33/$B$6) | F33: =IF(OR(B33="",$B$6=0),"",SUM($C$9:C33)/$B$6) | I33: =IF(Setup!D29="","",IF(SUMPRODUCT(--(Setup!$D$4:D28=Setup!D29))>0,"",Setup!D29)) | J33: =IF(I33="",0,SUMPRODUCT(('Downtime Log'!$H$5:$H$1004=I33)*('Downtime Log'!$A$5:$A$1004>=$D$3)*('Downtime Log'!$A$5:$A$1004<=$D$4)*((($B$5="")+('Downtime Log'!$C$5:$C$1004=$B$5))>0),'Downtime Log'!$G$5:$G$1004)) -> 0 | K33: =IF(I33="",0,SUMPRODUCT(('Downtime Log'!$H$5:$H$1004=I33)*('Downtime Log'!$A$5:$A$1004>=$D$3)*('Downtime Log'!$A$5:$A$1004<=$D$4)*((($B$5="")+('Downtime Log'!$C$5:$C$1004=$B$5))>0)*ISNUMBER('Downtime Log'!$G$5:$G$1004)*('Downtime Log'!$G$5:$G$1004>0))) -> 0 | L33: =IF(I33="",-1,J33+(34-25)/1000000) -> -1
A34: 26 | B34: =IF(INDEX($J$9:$J$38,MATCH(LARGE($L$9:$L$38,A34),$L$9:$L$38,0))<=0,"",INDEX($I$9:$I$38,MATCH(LARGE($L$9:$L$38,A34),$L$9:$L$38,0))) | C34: =IF(B34="","",INDEX($J$9:$J$38,MATCH(LARGE($L$9:$L$38,A34),$L$9:$L$38,0))) | D34: =IF(B34="","",INDEX($K$9:$K$38,MATCH(LARGE($L$9:$L$38,A34),$L$9:$L$38,0))) | E34: =IF(OR(B34="",$B$6=0),"",C34/$B$6) | F34: =IF(OR(B34="",$B$6=0),"",SUM($C$9:C34)/$B$6) | I34: =IF(Setup!D30="","",IF(SUMPRODUCT(--(Setup!$D$4:D29=Setup!D30))>0,"",Setup!D30)) | J34: =IF(I34="",0,SUMPRODUCT(('Downtime Log'!$H$5:$H$1004=I34)*('Downtime Log'!$A$5:$A$1004>=$D$3)*('Downtime Log'!$A$5:$A$1004<=$D$4)*((($B$5="")+('Downtime Log'!$C$5:$C$1004=$B$5))>0),'Downtime Log'!$G$5:$G$1004)) -> 0 | K34: =IF(I34="",0,SUMPRODUCT(('Downtime Log'!$H$5:$H$1004=I34)*('Downtime Log'!$A$5:$A$1004>=$D$3)*('Downtime Log'!$A$5:$A$1004<=$D$4)*((($B$5="")+('Downtime Log'!$C$5:$C$1004=$B$5))>0)*ISNUMBER('Downtime Log'!$G$5:$G$1004)*('Downtime Log'!$G$5:$G$1004>0))) -> 0 | L34: =IF(I34="",-1,J34+(34-26)/1000000) -> -1
A35: 27 | B35: =IF(INDEX($J$9:$J$38,MATCH(LARGE($L$9:$L$38,A35),$L$9:$L$38,0))<=0,"",INDEX($I$9:$I$38,MATCH(LARGE($L$9:$L$38,A35),$L$9:$L$38,0))) | C35: =IF(B35="","",INDEX($J$9:$J$38,MATCH(LARGE($L$9:$L$38,A35),$L$9:$L$38,0))) | D35: =IF(B35="","",INDEX($K$9:$K$38,MATCH(LARGE($L$9:$L$38,A35),$L$9:$L$38,0))) | E35: =IF(OR(B35="",$B$6=0),"",C35/$B$6) | F35: =IF(OR(B35="",$B$6=0),"",SUM($C$9:C35)/$B$6) | I35: =IF(Setup!D31="","",IF(SUMPRODUCT(--(Setup!$D$4:D30=Setup!D31))>0,"",Setup!D31)) | J35: =IF(I35="",0,SUMPRODUCT(('Downtime Log'!$H$5:$H$1004=I35)*('Downtime Log'!$A$5:$A$1004>=$D$3)*('Downtime Log'!$A$5:$A$1004<=$D$4)*((($B$5="")+('Downtime Log'!$C$5:$C$1004=$B$5))>0),'Downtime Log'!$G$5:$G$1004)) -> 0 | K35: =IF(I35="",0,SUMPRODUCT(('Downtime Log'!$H$5:$H$1004=I35)*('Downtime Log'!$A$5:$A$1004>=$D$3)*('Downtime Log'!$A$5:$A$1004<=$D$4)*((($B$5="")+('Downtime Log'!$C$5:$C$1004=$B$5))>0)*ISNUMBER('Downtime Log'!$G$5:$G$1004)*('Downtime Log'!$G$5:$G$1004>0))) -> 0 | L35: =IF(I35="",-1,J35+(34-27)/1000000) -> -1
A36: 28 | B36: =IF(INDEX($J$9:$J$38,MATCH(LARGE($L$9:$L$38,A36),$L$9:$L$38,0))<=0,"",INDEX($I$9:$I$38,MATCH(LARGE($L$9:$L$38,A36),$L$9:$L$38,0))) | C36: =IF(B36="","",INDEX($J$9:$J$38,MATCH(LARGE($L$9:$L$38,A36),$L$9:$L$38,0))) | D36: =IF(B36="","",INDEX($K$9:$K$38,MATCH(LARGE($L$9:$L$38,A36),$L$9:$L$38,0))) | E36: =IF(OR(B36="",$B$6=0),"",C36/$B$6) | F36: =IF(OR(B36="",$B$6=0),"",SUM($C$9:C36)/$B$6) | I36: =IF(Setup!D32="","",IF(SUMPRODUCT(--(Setup!$D$4:D31=Setup!D32))>0,"",Setup!D32)) | J36: =IF(I36="",0,SUMPRODUCT(('Downtime Log'!$H$5:$H$1004=I36)*('Downtime Log'!$A$5:$A$1004>=$D$3)*('Downtime Log'!$A$5:$A$1004<=$D$4)*((($B$5="")+('Downtime Log'!$C$5:$C$1004=$B$5))>0),'Downtime Log'!$G$5:$G$1004)) -> 0 | K36: =IF(I36="",0,SUMPRODUCT(('Downtime Log'!$H$5:$H$1004=I36)*('Downtime Log'!$A$5:$A$1004>=$D$3)*('Downtime Log'!$A$5:$A$1004<=$D$4)*((($B$5="")+('Downtime Log'!$C$5:$C$1004=$B$5))>0)*ISNUMBER('Downtime Log'!$G$5:$G$1004)*('Downtime Log'!$G$5:$G$1004>0))) -> 0 | L36: =IF(I36="",-1,J36+(34-28)/1000000) -> -1
A37: 29 | B37: =IF(INDEX($J$9:$J$38,MATCH(LARGE($L$9:$L$38,A37),$L$9:$L$38,0))<=0,"",INDEX($I$9:$I$38,MATCH(LARGE($L$9:$L$38,A37),$L$9:$L$38,0))) | C37: =IF(B37="","",INDEX($J$9:$J$38,MATCH(LARGE($L$9:$L$38,A37),$L$9:$L$38,0))) | D37: =IF(B37="","",INDEX($K$9:$K$38,MATCH(LARGE($L$9:$L$38,A37),$L$9:$L$38,0))) | E37: =IF(OR(B37="",$B$6=0),"",C37/$B$6) | F37: =IF(OR(B37="",$B$6=0),"",SUM($C$9:C37)/$B$6) | I37: =IF(Setup!D33="","",IF(SUMPRODUCT(--(Setup!$D$4:D32=Setup!D33))>0,"",Setup!D33)) | J37: =IF(I37="",0,SUMPRODUCT(('Downtime Log'!$H$5:$H$1004=I37)*('Downtime Log'!$A$5:$A$1004>=$D$3)*('Downtime Log'!$A$5:$A$1004<=$D$4)*((($B$5="")+('Downtime Log'!$C$5:$C$1004=$B$5))>0),'Downtime Log'!$G$5:$G$1004)) -> 0 | K37: =IF(I37="",0,SUMPRODUCT(('Downtime Log'!$H$5:$H$1004=I37)*('Downtime Log'!$A$5:$A$1004>=$D$3)*('Downtime Log'!$A$5:$A$1004<=$D$4)*((($B$5="")+('Downtime Log'!$C$5:$C$1004=$B$5))>0)*ISNUMBER('Downtime Log'!$G$5:$G$1004)*('Downtime Log'!$G$5:$G$1004>0))) -> 0 | L37: =IF(I37="",-1,J37+(34-29)/1000000) -> -1
A38: 30 | B38: =IF(INDEX($J$9:$J$38,MATCH(LARGE($L$9:$L$38,A38),$L$9:$L$38,0))<=0,"",INDEX($I$9:$I$38,MATCH(LARGE($L$9:$L$38,A38),$L$9:$L$38,0))) | C38: =IF(B38="","",INDEX($J$9:$J$38,MATCH(LARGE($L$9:$L$38,A38),$L$9:$L$38,0))) | D38: =IF(B38="","",INDEX($K$9:$K$38,MATCH(LARGE($L$9:$L$38,A38),$L$9:$L$38,0))) | E38: =IF(OR(B38="",$B$6=0),"",C38/$B$6) | F38: =IF(OR(B38="",$B$6=0),"",SUM($C$9:C38)/$B$6) | I38: =IF(Setup!D34="","",IF(SUMPRODUCT(--(Setup!$D$4:D33=Setup!D34))>0,"",Setup!D34)) | J38: =IF(I38="",0,SUMPRODUCT(('Downtime Log'!$H$5:$H$1004=I38)*('Downtime Log'!$A$5:$A$1004>=$D$3)*('Downtime Log'!$A$5:$A$1004<=$D$4)*((($B$5="")+('Downtime Log'!$C$5:$C$1004=$B$5))>0),'Downtime Log'!$G$5:$G$1004)) -> 0 | K38: =IF(I38="",0,SUMPRODUCT(('Downtime Log'!$H$5:$H$1004=I38)*('Downtime Log'!$A$5:$A$1004>=$D$3)*('Downtime Log'!$A$5:$A$1004<=$D$4)*((($B$5="")+('Downtime Log'!$C$5:$C$1004=$B$5))>0)*ISNUMBER('Downtime Log'!$G$5:$G$1004)*('Downtime Log'!$G$5:$G$1004>0))) -> 0 | L38: =IF(I38="",-1,J38+(34-30)/1000000) -> -1

Sheet By Machine
A1: Downtime by Machine
A2: Uses the date range set on the Pareto sheet (machine filter is ignored here). A stop is any row with more than 0 minutes.
A4: Machine | B4: Downtime (min) | C4: Stops | D4: Avg min per stop | E4: % of all downtime
A5: =IF(Setup!A5="","",IF(SUMPRODUCT(--(Setup!$A$4:A4=Setup!A5))>0,"",Setup!A5)) -> Press 01 | B5: =IF($A5="","",SUMPRODUCT(('Downtime Log'!$C$5:$C$1004=$A5)*('Downtime Log'!$A$5:$A$1004>=Pareto!$D$3)*('Downtime Log'!$A$5:$A$1004<=Pareto!$D$4),'Downtime Log'!$G$5:$G$1004)) -> 105 | C5: =IF($A5="","",SUMPRODUCT(('Downtime Log'!$C$5:$C$1004=$A5)*('Downtime Log'!$A$5:$A$1004>=Pareto!$D$3)*('Downtime Log'!$A$5:$A$1004<=Pareto!$D$4)*ISNUMBER('Downtime Log'!$G$5:$G$1004)*('Downtime Log'!$G$5:$G$1004>0))) -> 3 | D5: =IF(OR($A5="",N(C5)=0),"",B5/C5) -> 35 | E5: =IF(OR($A5="",$B$36=0),"",B5/$B$36) -> 0.41176471
A6: =IF(Setup!A6="","",IF(SUMPRODUCT(--(Setup!$A$4:A5=Setup!A6))>0,"",Setup!A6)) -> CNC Lathe 02 | B6: =IF($A6="","",SUMPRODUCT(('Downtime Log'!$C$5:$C$1004=$A6)*('Downtime Log'!$A$5:$A$1004>=Pareto!$D$3)*('Downtime Log'!$A$5:$A$1004<=Pareto!$D$4),'Downtime Log'!$G$5:$G$1004)) -> 75 | C6: =IF($A6="","",SUMPRODUCT(('Downtime Log'!$C$5:$C$1004=$A6)*('Downtime Log'!$A$5:$A$1004>=Pareto!$D$3)*('Downtime Log'!$A$5:$A$1004<=Pareto!$D$4)*ISNUMBER('Downtime Log'!$G$5:$G$1004)*('Downtime Log'!$G$5:$G$1004>0))) -> 2 | D6: =IF(OR($A6="",N(C6)=0),"",B6/C6) -> 37.5 | E6: =IF(OR($A6="",$B$36=0),"",B6/$B$36) -> 0.29411765
A7: =IF(Setup!A7="","",IF(SUMPRODUCT(--(Setup!$A$4:A6=Setup!A7))>0,"",Setup!A7)) -> Packaging Line A | B7: =IF($A7="","",SUMPRODUCT(('Downtime Log'!$C$5:$C$1004=$A7)*('Downtime Log'!$A$5:$A$1004>=Pareto!$D$3)*('Downtime Log'!$A$5:$A$1004<=Pareto!$D$4),'Downtime Log'!$G$5:$G$1004)) -> 75 | C7: =IF($A7="","",SUMPRODUCT(('Downtime Log'!$C$5:$C$1004=$A7)*('Downtime Log'!$A$5:$A$1004>=Pareto!$D$3)*('Downtime Log'!$A$5:$A$1004<=Pareto!$D$4)*ISNUMBER('Downtime Log'!$G$5:$G$1004)*('Downtime Log'!$G$5:$G$1004>0))) -> 2 | D7: =IF(OR($A7="",N(C7)=0),"",B7/C7) -> 37.5 | E7: =IF(OR($A7="",$B$36=0),"",B7/$B$36) -> 0.29411765
